Workbook

Sheet Cover Sheet
A1: COMPREHENSIVE BILL OF QUANTITIES
A2: Project: Terminal 1 Expansion Project
A5: COST BREAKDOWN METHODOLOGY
A7: 1. MATERIAL COSTS
A8: Source: | B8: CIDB National Construction Cost Centre (N3C) 2024
A9: Reference: | B9: BCISM Cost Book 2022-2024 (inflated +3%)
A10: Includes: | B10: Delivery, wastage allowance (5-10% by material type)
A12: 2. LABOR COSTS
A13: Source: | B13: MBAM-CIDB Labour Wage Survey 2024
A14: Basis: | B14: Basic wage + 30% (EPF 13%, SOCSO 2%, benefits 15%)
A15: Productivity: | B15: CIDB productivity standards by trade
A16: Crew Composition: | B16: Skilled workers + helpers as per trade standards
A18: 3. EQUIPMENT/PLANT HIRE
A19: Source: | B19: CIDB N3C Machinery Hire Rates 2024
A20: Allocation: | B20: Based on work type and duration requirements
A21: Rates: | B21: Per day (8 hours), operator cost included where stated
A23: COST SUMMARY STRUCTURE
A24: Sheet 1: | B24: Cover Sheet (this page)
A25: Sheet 2: | B25: Executive Summary - Total costs with charts
A26: Sheet 3: | B26: Materials Cost Summary | C26: Detailed material breakdown
A27: Sheet 4: | B27: Labor Cost Summary | C27: Crew allocation & man-days
A28: Sheet 5: | B28: Equipment Cost Summary | C28: Plant hire requirements
A29: Sheet 6+: | B29: Detailed BOQ by Discipline | C29: Line-by-line analysis
A31: PRICING STANDARDS & REFERENCES
A32: BOQ Format: | B32: PWD Form 203A Malaysia
A33: Measurement: | B33: SMM2 (Standard Method of Measurement)
A34: Pricing Date: | B34: Q4 2024
A35: Currency: | B35: Malaysian Ringgit (RM)
A36: Validity: | B36: 60 days from date of issue
A38: EXCLUSIONS
A39: • GST/SST (apply as per prevailing tax law)
A40: • Preliminary & General items (add 8-12%)
A41: • Profit & attendance (add 10-15%)
A42: • Escalation beyond 60 days
A43: • Site-specific conditions not shown in drawings

Sheet Executive Summary
A1: EXECUTIVE SUMMARY
A3: Discipline | B3: Material (RM) | C3: Labor (RM) | D3: Equipment (RM) | E3: TOTAL (RM)
A4: ACMV | B4: ='BOQ - ACMV'!F23 | C4: ='BOQ - ACMV'!G23 | D4: ='BOQ - ACMV'!H23 | E4: ='BOQ - ACMV'!I23
A5: ARC | B5: ='BOQ - ARC'!F62 | C5: ='BOQ - ARC'!G62 | D5: ='BOQ - ARC'!H62 | E5: ='BOQ - ARC'!I62
A6: ELEC | B6: ='BOQ - ELEC'!F57 | C6: ='BOQ - ELEC'!G57 | D6: ='BOQ - ELEC'!H57 | E6: ='BOQ - ELEC'!I57
A7: FP | B7: ='BOQ - FP'!F59 | C7: ='BOQ - FP'!G59 | D7: ='BOQ - FP'!H59 | E7: ='BOQ - FP'!I59
A8: STR | B8: ='BOQ - STR'!F99 | C8: ='BOQ - STR'!G99 | D8: ='BOQ - STR'!H99 | E8: ='BOQ - STR'!I99
A9: FINISHES & FITTINGS | E9: ='Provisional Sums'!G16
A11: GRAND TOTAL | B11: =SUM(B4:B9) | C11: =SUM(C4:C9) | D11: =SUM(D4:D9) | E11: =SUM(E4:E9)

Sheet BOQ - ACMV
A1: DETAILED BOQ - ACMV
A3: Item | B3: Description | C3: Qty | D3: UOM | E3: Material Rate (RM) | F3: Material Cost (RM) | G3: Labor Cost (RM) | H3: Equipment Cost (RM) | I3: Total (RM)
A4: 001 | B4: IfcAirTerminal | C4: 40 | D4: EA | E4: 0 | F4: =C4*E4 | G4: 0 | H4: 0 | I4: =F4+G4+H4
A5: 002 | B5: IfcAirTerminal | C5: 10 | D5: EA | E5: 0 | F5: =C5*E5 | G5: 0 | H5: 0 | I5: =F5+G5+H5
A6: 003 | B6: IfcAirTerminal | C6: 10 | D6: EA | E6: 0 | F6: =C6*E6 | G6: 0 | H6: 0 | I6: =F6+G6+H6
A7: 004 | B7: IfcAirTerminal | C7: 10 | D7: EA | E7: 0 | F7: =C7*E7 | G7: 0 | H7: 0 | I7: =F7+G7+H7
A8: 005 | B8: IfcAirTerminal | C8: 10 | D8: EA | E8: 0 | F8: =C8*E8 | G8: 0 | H8: 0 | I8: =F8+G8+H8
A9: 006 | B9: IfcAirTerminal | C9: 10 | D9: EA | E9: 0 | F9: =C9*E9 | G9: 0 | H9: 0 | I9: =F9+G9+H9
A10: 007 | B10: IfcAirTerminal | C10: 10 | D10: EA | E10: 0 | F10: =C10*E10 | G10: 0 | H10: 0 | I10: =F10+G10+H10
A11: 008 | B11: IfcAirTerminal | C11: 10 | D11: EA | E11: 0 | F11: =C11*E11 | G11: 0 | H11: 0 | I11: =F11+G11+H11
A12: 009 | B12: IfcAirTerminal | C12: 10 | D12: EA | E12: 0 | F12: =C12*E12 | G12: 0 | H12: 0 | I12: =F12+G12+H12
A13: 010 | B13: IfcAirTerminal | C13: 10 | D13: EA | E13: 0 | F13: =C13*E13 | G13: 0 | H13: 0 | I13: =F13+G13+H13
A14: 011 | B14: IfcAirTerminal | C14: 10 | D14: EA | E14: 0 | F14: =C14*E14 | G14: 0 | H14: 0 | I14: =F14+G14+H14
A15: 012 | B15: IfcAirTerminal | C15: 10 | D15: EA | E15: 0 | F15: =C15*E15 | G15: 0 | H15: 0 | I15: =F15+G15+H15
... A21: 018 | B21: IfcAirTerminal | C21: 10 | D21: EA | E21: 0 | F21: =C21*E21 | G21: 0 | H21: 0 | I21: =F21+G21+H21
A23: TOTAL - ACMV | F23: =SUM(F4:F21) | G23: =SUM(G4:G21) | H23: =SUM(H4:H21) | I23: =SUM(I4:I21)

Sheet BOQ - ARC
A1: DETAILED BOQ - ARC
A3: Item | B3: Description | C3: Qty | D3: UOM | E3: Material Rate (RM) | F3: Material Cost (RM) | G3: Labor Cost (RM) | H3: Equipment Cost (RM) | I3: Total (RM)
A4: 001 | B4: Metal Deck Roofing with Insulation | C4: 1348.5 | D4: M2 | E4: 238 | F4: =C4*E4 | G4: 0 | H4: 0 | I4: =F4+G4+H4
A5: 002 | B5: IfcFurniture | C5: 56 | D5: EA | E5: 0 | F5: =C5*E5 | G5: 0 | H5: 0 | I5: =F5+G5+H5
A6: 003 | B6: IfcPlate | C6: 54.86 | D6: M2 | E6: 0 | F6: =C6*E6 | G6: 0 | H6: 0 | I6: =F6+G6+H6
A7: 004 | B7: IfcPlate | C7: 28.65 | D7: M2 | E7: 0 | F7: =C7*E7 | G7: 0 | H7: 0 | I7: =F7+G7+H7
A8: 005 | B8: IfcPlate | C8: 28.65 | D8: M2 | E8: 0 | F8: =C8*E8 | G8: 0 | H8: 0 | I8: =F8+G8+H8
A9: 006 | B9: IfcPlate | C9: 28.65 | D9: M2 | E9: 0 | F9: =C9*E9 | G9: 0 | H9: 0 | I9: =F9+G9+H9
A10: 007 | B10: IfcPlate | C10: 28.65 | D10: M2 | E10: 0 | F10: =C10*E10 | G10: 0 | H10: 0 | I10: =F10+G10+H10
A11: 008 | B11: IfcPlate | C11: 28.65 | D11: M2 | E11: 0 | F11: =C11*E11 | G11: 0 | H11: 0 | I11: =F11+G11+H11
A12: 009 | B12: IfcPlate | C12: 28.65 | D12: M2 | E12: 0 | F12: =C12*E12 | G12: 0 | H12: 0 | I12: =F12+G12+H12
A13: 010 | B13: IfcPlate | C13: 28.65 | D13: M2 | E13: 0 | F13: =C13*E13 | G13: 0 | H13: 0 | I13: =F13+G13+H13
A14: 011 | B14: IfcPlate | C14: 28.65 | D14: M2 | E14: 0 | F14: =C14*E14 | G14: 0 | H14: 0 | I14: =F14+G14+H14
A15: 012 | B15: IfcPlate | C15: 28.65 | D15: M2 | E15: 0 | F15: =C15*E15 | G15: 0 | H15: 0 | I15: =F15+G15+H15
... A60: 057 | B60: IfcStairFlight | C60: 2 | D60: EA | E60: 0 | F60: =C60*E60 | G60: 0 | H60: 0 | I60: =F60+G60+H60
A62: TOTAL - ARC | F62: =SUM(F4:F60) | G62: =SUM(G4:G60) | H62: =SUM(H4:H60) | I62: =SUM(I4:I60)

Sheet BOQ - ELEC
A1: DETAILED BOQ - ELEC
A3: Item | B3: Description | C3: Qty | D3: UOM | E3: Material Rate (RM) | F3: Material Cost (RM) | G3: Labor Cost (RM) | H3: Equipment Cost (RM) | I3: Total (RM)
A4: 001 | B4: 13A Power Outlet - Airport Spec | C4: 6 | D4: EA | E4: 125 | F4: =C4*E4 | G4: 84 | H4: 0 | I4: =F4+G4+H4
A5: 002 | B5: LED Light Fixture - Airport Grade | C5: 5 | D5: EA | E5: 485 | F5: =C5*E5 | G5: 87.5 | H5: 0 | I5: =F5+G5+H5
A6: 003 | B6: LED Light Fixture - Airport Grade | C6: 5 | D6: EA | E6: 485 | F6: =C6*E6 | G6: 87.5 | H6: 0 | I6: =F6+G6+H6
A7: 004 | B7: LED Light Fixture - Airport Grade | C7: 5 | D7: EA | E7: 485 | F7: =C7*E7 | G7: 87.5 | H7: 0 | I7: =F7+G7+H7
A8: 005 | B8: LED Light Fixture - Airport Grade | C8: 5 | D8: EA | E8: 485 | F8: =C8*E8 | G8: 87.5 | H8: 0 | I8: =F8+G8+H8
A9: 006 | B9: LED Light Fixture - Airport Grade | C9: 5 | D9: EA | E9: 485 | F9: =C9*E9 | G9: 87.5 | H9: 0 | I9: =F9+G9+H9
A10: 007 | B10: LED Light Fixture - Airport Grade | C10: 5 | D10: EA | E10: 485 | F10: =C10*E10 | G10: 87.5 | H10: 0 | I10: =F10+G10+H10
A11: 008 | B11: LED Light Fixture - Airport Grade | C11: 5 | D11: EA | E11: 485 | F11: =C11*E11 | G11: 87.5 | H11: 0 | I11: =F11+G11+H11
A12: 009 | B12: LED Light Fixture - Airport Grade | C12: 5 | D12: EA | E12: 485 | F12: =C12*E12 | G12: 87.5 | H12: 0 | I12: =F12+G12+H12
A13: 010 | B13: LED Light Fixture - Airport Grade | C13: 5 | D13: EA | E13: 485 | F13: =C13*E13 | G13: 87.5 | H13: 0 | I13: =F13+G13+H13
A14: 011 | B14: LED Light Fixture - Airport Grade | C14: 5 | D14: EA | E14: 485 | F14: =C14*E14 | G14: 87.5 | H14: 0 | I14: =F14+G14+H14
A15: 012 | B15: LED Light Fixture - Airport Grade | C15: 5 | D15: EA | E15: 485 | F15: =C15*E15 | G15: 87.5 | H15: 0 | I15: =F15+G15+H15
... A55: 052 | B55: 13A Power Outlet - Airport Spec | C55: 1 | D55: EA | E55: 125 | F55: =C55*E55 | G55: 14 | H55: 0 | I55: =F55+G55+H55
A57: TOTAL - ELEC | F57: =SUM(F4:F55) | G57: =SUM(G4:G55) | H57: =SUM(H4:H55) | I57: =SUM(I4:I55)

Sheet BOQ - FP
A1: DETAILED BOQ - FP
A3: Item | B3: Description | C3: Qty | D3: UOM | E3: Material Rate (RM) | F3: Material Cost (RM) | G3: Labor Cost (RM) | H3: Equipment Cost (RM) | I3: Total (RM)
A4: 001 | B4: IfcFireSuppressionTerminal | C4: 14 | D4: EA | E4: 0 | F4: =C4*E4 | G4: 0 | H4: 0 | I4: =F4+G4+H4
A5: 002 | B5: Pipe Segment | C5: 9.56 | D5: M | E5: 48.5 | F5: =C5*E5 | G5: 126.192 | H5: 0 | I5: =F5+G5+H5
A6: 003 | B6: IfcFireSuppressionTerminal | C6: 6 | D6: EA | E6: 0 | F6: =C6*E6 | G6: 0 | H6: 0 | I6: =F6+G6+H6
A7: 004 | B7: IfcFireSuppressionTerminal | C7: 6 | D7: EA | E7: 0 | F7: =C7*E7 | G7: 0 | H7: 0 | I7: =F7+G7+H7
A8: 005 | B8: IfcFireSuppressionTerminal | C8: 6 | D8: EA | E8: 0 | F8: =C8*E8 | G8: 0 | H8: 0 | I8: =F8+G8+H8
A9: 006 | B9: IfcFireSuppressionTerminal | C9: 6 | D9: EA | E9: 0 | F9: =C9*E9 | G9: 0 | H9: 0 | I9: =F9+G9+H9
A10: 007 | B10: IfcFireSuppressionTerminal | C10: 6 | D10: EA | E10: 0 | F10: =C10*E10 | G10: 0 | H10: 0 | I10: =F10+G10+H10
A11: 008 | B11: IfcFireSuppressionTerminal | C11: 6 | D11: EA | E11: 0 | F11: =C11*E11 | G11: 0 | H11: 0 | I11: =F11+G11+H11
A12: 009 | B12: IfcFireSuppressionTerminal | C12: 6 | D12: EA | E12: 0 | F12: =C12*E12 | G12: 0 | H12: 0 | I12: =F12+G12+H12
A13: 010 | B13: IfcFireSuppressionTerminal | C13: 6 | D13: EA | E13: 0 | F13: =C13*E13 | G13: 0 | H13: 0 | I13: =F13+G13+H13
A14: 011 | B14: IfcFireSuppressionTerminal | C14: 6 | D14: EA | E14: 0 | F14: =C14*E14 | G14: 0 | H14: 0 | I14: =F14+G14+H14
A15: 012 | B15: IfcFireSuppressionTerminal | C15: 6 | D15: EA | E15: 0 | F15: =C15*E15 | G15: 0 | H15: 0 | I15: =F15+G15+H15
... A57: 054 | B57: Pipe Fittings | C57: 0.27 | D57: M | E57: 95 | F57: =C57*E57 | G57: 5.94 | H57: 0 | I57: =F57+G57+H57
A59: TOTAL - FP | F59: =SUM(F4:F57) | G59: =SUM(G4:G57) | H59: =SUM(H4:H57) | I59: =SUM(I4:I57)

Sheet BOQ - STR
A1: DETAILED BOQ - STR
A3: Item | B3: Description | C3: Qty | D3: UOM | E3: Material Rate (RM) | F3: Material Cost (RM) | G3: Labor Cost (RM) | H3: Equipment Cost (RM) | I3: Total (RM)
A4: 001 | B4: IfcSpace | C4: 3213 | D4: M3 | E4: 0 | F4: =C4*E4 | G4: 0 | H4: 0 | I4: =F4+G4+H4
A5: 002 | B5: RC Slab - Airport Grade (250mm) | C5: 1224.33 | D5: M2 | E5: 285 | F5: =C5*E5 | G5: 30433.346 | H5: 9969.5443 | I5: =F5+G5+H5
A6: 003 | B6: IfcSpace | C6: 1122 | D6: M3 | E6: 0 | F6: =C6*E6 | G6: 0 | H6: 0 | I6: =F6+G6+H6
A7: 004 | B7: IfcSpace | C7: 1122 | D7: M3 | E7: 0 | F7: =C7*E7 | G7: 0 | H7: 0 | I7: =F7+G7+H7
A8: 005 | B8: IfcSpace | C8: 1122 | D8: M3 | E8: 0 | F8: =C8*E8 | G8: 0 | H8: 0 | I8: =F8+G8+H8
A9: 006 | B9: IfcSpace | C9: 1122 | D9: M3 | E9: 0 | F9: =C9*E9 | G9: 0 | H9: 0 | I9: =F9+G9+H9
A10: 007 | B10: IfcSpace | C10: 1122 | D10: M3 | E10: 0 | F10: =C10*E10 | G10: 0 | H10: 0 | I10: =F10+G10+H10
A11: 008 | B11: IfcSpace | C11: 1122 | D11: M3 | E11: 0 | F11: =C11*E11 | G11: 0 | H11: 0 | I11: =F11+G11+H11
A12: 009 | B12: IfcSpace | C12: 1122 | D12: M3 | E12: 0 | F12: =C12*E12 | G12: 0 | H12: 0 | I12: =F12+G12+H12
A13: 010 | B13: IfcSpace | C13: 1122 | D13: M3 | E13: 0 | F13: =C13*E13 | G13: 0 | H13: 0 | I13: =F13+G13+H13
A14: 011 | B14: IfcSpace | C14: 1122 | D14: M3 | E14: 0 | F14: =C14*E14 | G14: 0 | H14: 0 | I14: =F14+G14+H14
A15: 012 | B15: IfcSpace | C15: 1122 | D15: M3 | E15: 0 | F15: =C15*E15 | G15: 0 | H15: 0 | I15: =F15+G15+H15
... A97: 094 | B97: Structural Steel I-Beam - Airport Spec | C97: 0.2 | D97: M | E97: 680 | F97: =C97*E97 | G97: 19.5 | H97: 23.125 | I97: =F97+G97+H97
A99: TOTAL - STR | F99: =SUM(F4:F97) | G99: =SUM(G4:G97) | H99: =SUM(H4:H97) | I99: =SUM(I4:I97)

Sheet Work Packages
A1: WORK PACKAGES - CONSTRUCTION PHASING
A2: Organized by typical construction sequence for scheduling
A4: PACKAGE 1: SUBSTRUCTURE
A5: Discipline | B5: Element Type | C5: Quantity | D5: UOM | E5: Material | F5: Labor | G5: Equipment | H5: Total (RM)
A6: STR | B6: IfcColumn | C6: 294 | D6: M | E6: 367500 | F6: 38220 | G6: 45325 | H6: 451045
A7: STR | B7: IfcColumn | C7: 24 | D7: M | E7: 30000 | F7: 3120 | G7: 3700 | H7: 36820
A8: STR | B8: IfcColumn | C8: 18 | D8: M | E8: 22500 | F8: 2340 | G8: 2775 | H8: 27615
A9: STR | B9: IfcBeam | C9: 2.2 | D9: M | E9: 1496 | F9: 214.5 | G9: 254.375 | H9: 1964.875
A10: STR | B10: IfcBeam | C10: 0.4 | D10: M | E10: 272 | F10: 39 | G10: 46.25 | H10: 357.25
A11: STR | B11: IfcBeam | C11: 0.4 | D11: M | E11: 272 | F11: 39 | G11: 46.25 | H11: 357.25
A12: STR | B12: IfcBeam | C12: 0.4 | D12: M | E12: 272 | F12: 39 | G12: 46.25 | H12: 357.25
A13: STR | B13: IfcBeam | C13: 0.4 | D13: M | E13: 272 | F13: 39 | G13: 46.25 | H13: 357.25
A14: STR | B14: IfcBeam | C14: 0.4 | D14: M | E14: 272 | F14: 39 | G14: 46.25 | H14: 357.25
A15: STR | B15: IfcBeam | C15: 0.4 | D15: M | E15: 272 | F15: 39 | G15: 46.25 | H15: 357.25
A16: STR | B16: IfcBeam | C16: 0.4 | D16: M | E16: 272 | F16: 39 | G16: 46.25 | H16: 357.25
A17: STR | B17: IfcBeam | C17: 0.4 | D17: M | E17: 272 | F17: 39 | G17: 46.25 | H17: 357.25
... A26: STR | B26: IfcBeam | C26: 0.2 | D26: M | E26: 136 | F26: 19.5 | G26: 23.125 | H26: 178.625
A27: SUBTOTAL - SUBSTRUCTURE | E27: =SUM(E6:E26) | F27: =SUM(F6:F26) | G27: =SUM(G6:G26) | H27: =SUM(H6:H26)
A29: PACKAGE 2: SUPERSTRUCTURE
A30: Discipline | B30: Element Type | C30: Quantity | D30: UOM | E30: Material | F30: Labor | G30: Equipment | H30: Total (RM)
A31: ARC | B31: IfcRoof | C31: 1348.5 | D31: M2 | E31: 320943 | F31: 0 | G31: 0 | H31: 320943
A32: STR | B32: IfcSlab | C32: 1224.33 | D32: M2 | E32: 348934.05 | F32: 30433.346 | G32: 9969.5443 | H32: 389336.94
A33: STR | B33: IfcSlab | C33: 446.16 | D33: M2 | E33: 127155.6 | F33: 11090.263 | G33: 3633.0171 | H33: 141878.88
A34: STR | B34: IfcSlab | C34: 446.16 | D34: M2 | E34: 127155.6 | F34: 11090.263 | G34: 3633.0171 | H34: 141878.88
A35: STR | B35: IfcSlab | C35: 446.16 | D35: M2 | E35: 127155.6 | F35: 11090.263 | G35: 3633.0171 | H35: 141878.88
A36: STR | B36: IfcSlab | C36: 446.16 | D36: M2 | E36: 127155.6 | F36: 11090.263 | G36: 3633.0171 | H36: 141878.88
A37: STR | B37: IfcSlab | C37: 446.16 | D37: M2 | E37: 127155.6 | F37: 11090.263 | G37: 3633.0171 | H37: 141878.88
A38: STR | B38: IfcSlab | C38: 446.16 | D38: M2 | E38: 127155.6 | F38: 11090.263 | G38: 3633.0171 | H38: 141878.88
A39: STR | B39: IfcSlab | C39: 446.16 | D39: M2 | E39: 127155.6 | F39: 11090.263 | G39: 3633.0171 | H39: 141878.88
A40: STR | B40: IfcSlab | C40: 446.16 | D40: M2 | E40: 127155.6 | F40: 11090.263 | G40: 3633.0171 | H40: 141878.88
A41: STR | B41: IfcSlab | C41: 446.16 | D41: M2 | E41: 127155.6 | F41: 11090.263 | G41: 3633.0171 | H41: 141878.88
A42: STR | B42: IfcSlab | C42: 446.16 | D42: M2 | E42: 127155.6 | F42: 11090.263 | G42: 3633.0171 | H42: 141878.88
... A49: STR | B49: IfcSlab | C49: 245.79 | D49: M2 | E49: 70050.15 | F49: 6109.6371 | G49: 2001.4329 | H49: 78161.22
A50: SUBTOTAL - SUPERSTRUCTURE | E50: =SUM(E31:E49) | F50: =SUM(F31:F49) | G50: =SUM(G31:G49) | H50: =SUM(H31:H49)
A52: PACKAGE 3: MEP ROUGH-IN
A53: Discipline | B53: Element Type | C53: Quantity | D53: UOM | E53: Material | F53: Labor | G53: Equipment | H53: Total (RM)
A54: FP | B54: IfcPipeSegment | C54: 9.56 | D54: M | E54: 463.66 | F54: 126.192 | G54: 0 | H54: 589.852
A55: FP | B55: IfcPipeSegment | C55: 5.95 | D55: M | E55: 288.575 | F55: 78.54 | G55: 0 | H55: 367.115
A56: FP | B56: IfcPipeSegment | C56: 5.95 | D56: M | E56: 288.575 | F56: 78.54 | G56: 0 | H56: 367.115
A57: FP | B57: IfcPipeSegment | C57: 5.95 | D57: M | E57: 288.575 | F57: 78.54 | G57: 0 | H57: 367.115
...

Sheet Provisional Sums
A1: PROVISIONAL SUMS - FINISHES & FITTINGS
A2: Items not explicitly modeled in BIM - calculated from built-up areas
A4: Item | B4: Description | C4: Qty | D4: UOM | E4: Material Rate (RM) | F4: Labor Rate (RM) | G4: Total (RM)
A5: P1 | B5: Painting - Walls and Ceilings (Dulux/Nippon 2 coats emulsion, primer, preparation) | C5: 0 | D5: M2 | E5: 8.5 | F5: 12 | G5: =C5*(E5+F5)
A6: P2 | B6: Check-in Counters & Service Desks (Solid surface, modular system, cable mgmt, branding) | C6: 15 | D6: EA | E6: 12500 | F6: 2500 | G6: =C6*(E6+F6)
A7: P3 | B7: Passenger Seating - Waiting Areas (Airport beam seating, 3-4 seater units, steel frame) | C7: 250 | D7: EA | E7: 580 | F7: 45 | G7: =C7*(E7+F7)
A8: P4 | B8: Wayfinding Signage System (Illuminated, bilingual, airport pictograms) | C8: 80 | D8: EA | E8: 650 | F8: 120 | G8: =C8*(E8+F8)
A9: P5 | B9: Flight Information Display Systems (FIDS) (55" LED, networked, real-time updates) | C9: 25 | D9: EA | E9: 8500 | F9: 1200 | G9: =C9*(E9+F9)
A10: P6 | B10: Baggage Trolley Storage Racks (Stainless steel, capacity 30 trolleys each) | C10: 12 | D10: EA | E10: 1850 | F10: 350 | G10: =C10*(E10+F10)
A11: P7 | B11: Retail Kiosk Fit-outs (Shell) (Structural frame, services rough-in, ready for tenant) | C11: 8 | D11: EA | E11: 22000 | F11: 5500 | G11: =C11*(E11+F11)
A12: P8 | B12: Rubber Safety Flooring - High Traffic (Anti-slip, heavy duty, transition zones) | C12: 1291.302 | D12: M2 | E12: 95 | F12: 28 | G12: =C12*(E12+F12)
A13: P9 | B13: Acoustic Ceiling Panels - Special Areas (High absorption, Class A, fire-rated) | C13: 1721.736 | D13: M2 | E13: 135 | F13: 42 | G13: =C13*(E13+F13)
A14: P10 | B14: Bollards & Barriers - Security (Fixed/removable, stainless steel, crash-rated) | C14: 45 | D14: EA | E14: 1250 | F14: 280 | G14: =C14*(E14+F14)
A16: TOTAL PROVISIONAL SUMS | G16: =SUM(G5:G14)

Sheet Material Summary
A1: MATERIAL COST SUMMARY
A3: Discipline | B3: IFC Class | C3: Quantity | D3: UOM | E3: Unit Rate (RM) | F3: Total Material (RM)
A4: ACMV | B4: IfcAirTerminal | C4: 40 | D4: EA | E4: 0 | F4: 0
A5: ACMV | B5: IfcAirTerminal | C5: 10 | D5: EA | E5: 0 | F5: 0
A6: ACMV | B6: IfcAirTerminal | C6: 10 | D6: EA | E6: 0 | F6: 0
A7: ACMV | B7: IfcAirTerminal | C7: 10 | D7: EA | E7: 0 | F7: 0
A8: ACMV | B8: IfcAirTerminal | C8: 10 | D8: EA | E8: 0 | F8: 0
A9: ACMV | B9: IfcAirTerminal | C9: 10 | D9: EA | E9: 0 | F9: 0
A10: ACMV | B10: IfcAirTerminal | C10: 10 | D10: EA | E10: 0 | F10: 0
A11: ACMV | B11: IfcAirTerminal | C11: 10 | D11: EA | E11: 0 | F11: 0
A12: ACMV | B12: IfcAirTerminal | C12: 10 | D12: EA | E12: 0 | F12: 0
A13: ACMV | B13: IfcAirTerminal | C13: 10 | D13: EA | E13: 0 | F13: 0
A14: ACMV | B14: IfcAirTerminal | C14: 10 | D14: EA | E14: 0 | F14: 0
A15: ACMV | B15: IfcAirTerminal | C15: 10 | D15: EA | E15: 0 | F15: 0
... A278: STR | B278: IfcBeam | C278: 0.2 | D278: M | E278: 680 | F278: 136

Sheet Labor Summary
A1: LABOR COST & CREW ALLOCATION SUMMARY
A3: Discipline | B3: IFC Class | C3: Quantity | D3: UOM | E3: Trade | F3: Crew Size | G3: Man-Days | H3: Labor Cost (RM)
A4: ELEC | B4: IfcOutlet | C4: 6 | D4: EA | E4: Electrician (Skilled) | F4: 2 | G4: 0.48 | H4: 84
A5: ELEC | B5: IfcLightFixture | C5: 5 | D5: EA | E5: Electrician (Skilled) | F5: 2 | G5: 0.5 | H5: 87.5
A6: ELEC | B6: IfcLightFixture | C6: 5 | D6: EA | E6: Electrician (Skilled) | F6: 2 | G6: 0.5 | H6: 87.5
A7: ELEC | B7: IfcLightFixture | C7: 5 | D7: EA | E7: Electrician (Skilled) | F7: 2 | G7: 0.5 | H7: 87.5
A8: ELEC | B8: IfcLightFixture | C8: 5 | D8: EA | E8: Electrician (Skilled) | F8: 2 | G8: 0.5 | H8: 87.5
A9: ELEC | B9: IfcLightFixture | C9: 5 | D9: EA | E9: Electrician (Skilled) | F9: 2 | G9: 0.5 | H9: 87.5
A10: ELEC | B10: IfcLightFixture | C10: 5 | D10: EA | E10: Electrician (Skilled) | F10: 2 | G10: 0.5 | H10: 87.5
A11: ELEC | B11: IfcLightFixture | C11: 5 | D11: EA | E11: Electrician (Skilled) | F11: 2 | G11: 0.5 | H11: 87.5
A12: ELEC | B12: IfcLightFixture | C12: 5 | D12: EA | E12: Electrician (Skilled) | F12: 2 | G12: 0.5 | H12: 87.5
A13: ELEC | B13: IfcLightFixture | C13: 5 | D13: EA | E13: Electrician (Skilled) | F13: 2 | G13: 0.5 | H13: 87.5
A14: ELEC | B14: IfcLightFixture | C14: 5 | D14: EA | E14: Electrician (Skilled) | F14: 2 | G14: 0.5 | H14: 87.5
A15: ELEC | B15: IfcLightFixture | C15: 5 | D15: EA | E15: Electrician (Skilled) | F15: 2 | G15: 0.5 | H15: 87.5
... A113: STR | B113: IfcBeam | C113: 0.2 | D113: M | E113: Steel Erector (Skilled) | F113: 4 | G113: 0.1 | H113: 19.5

Sheet Equipment Summary
A1: EQUIPMENT / PLANT HIRE SUMMARY
A3: Discipline | B3: IFC Class | C3: Equipment | D3: Duration (days) | E3: Rate/Day (RM) | F3: Total (RM)
A4: STR | B4: IfcSlab | C4: Concrete Pump Truck | D4: 10.494257 | E4: 950 | F4: 9969.5443
A5: STR | B5: IfcSlab | C5: Concrete Pump Truck | D5: 3.8242286 | E5: 950 | F5: 3633.0171
A6: STR | B6: IfcSlab | C6: Concrete Pump Truck | D6: 3.8242286 | E6: 950 | F6: 3633.0171
A7: STR | B7: IfcSlab | C7: Concrete Pump Truck | D7: 3.8242286 | E7: 950 | F7: 3633.0171
A8: STR | B8: IfcSlab | C8: Concrete Pump Truck | D8: 3.8242286 | E8: 950 | F8: 3633.0171
A9: STR | B9: IfcSlab | C9: Concrete Pump Truck | D9: 3.8242286 | E9: 950 | F9: 3633.0171
A10: STR | B10: IfcSlab | C10: Concrete Pump Truck | D10: 3.8242286 | E10: 950 | F10: 3633.0171
A11: STR | B11: IfcSlab | C11: Concrete Pump Truck | D11: 3.8242286 | E11: 950 | F11: 3633.0171
A12: STR | B12: IfcSlab | C12: Concrete Pump Truck | D12: 3.8242286 | E12: 950 | F12: 3633.0171
A13: STR | B13: IfcSlab | C13: Concrete Pump Truck | D13: 3.8242286 | E13: 950 | F13: 3633.0171
A14: STR | B14: IfcSlab | C14: Concrete Pump Truck | D14: 3.8242286 | E14: 950 | F14: 3633.0171
A15: STR | B15: IfcSlab | C15: Concrete Pump Truck | D15: 3.8242286 | E15: 950 | F15: 3633.0171
... A42: STR | B42: IfcBeam | C42: Mobile Crane 20 Tonne | D42: 0.0125 | E42: 1850 | F42: 23.125
